Workbook

Sheet الموظفين
B2: بيانات الموظفين - كافية 2M
B4: م | C4: اسم الموظف | D4: الوظيفة | E4: رقم التلفون
B5: 1 | C5: عبد الله الغذالي | D5: سوبر فايزر | E5: 1099724995
B6: 2 | C6: محمد احمد صلاح احمد | D6: بارستا | E6: 1098610851
B7: 3 | C7: يوسف محمد شحته | D7: كابتن | E7: 1022948840
B8: 4 | C8: محمود عثمان فؤاد | D8: كابتن | E8: 1094787318
B9: 5 | C9: سيف فخري فوزي | D9: هاوس | E9: 1203252448
B10: 6 | C10: فارس | D10: ويتر | E10: 1273884672
B11: 7 | C11: محمد صبري محمد | D11: ويتر | E11: 1556027058
B12: 8 | C12: عمار محمد صبحي عبد الفتاح | D12: كاشير | E12: 1148115761
B13: 9 | C13: عيد نوح عيد نوح صالح | D13: محاسب | E13: 1097710346
B14: 10 | C14: ادم ياسر محمد | D14: هيد بار | E14: 1221210579
B15: 11 | C15: محمود محمد صبحي | D15: هاوس | E15: _
B16: 12 | C16: محمد رافت | D16: استيور | E16: _
B17: 13 | C17: احمد هشهش | D17: كابتن | E17: 1028966193
B18: 14 | C18: محمد اشرف | D18: استيور | E18: _
B19: 15 | C19: اسلام رمضان | D19: ويتر | E19: _
B20: 16 | C20: فهمي جمال | D20: بيكب | E20: 1277585870
B21: 17 | C21: محمد عزت | D21: ويتر | E21: 1020633821
B22: 18 | C22: عبد الرحمن ايهاب | D22: _ | E22: _
B23: 19 | C23: احمد الجهري | D23: _ | E23: _
B24: 20 | C24: احمد الطيب

Sheet المشتريات اليومية
A2: سجل المشاريات اليومية - يويلو 2026
A4: التاريخ | B4: اليوم | C4: الصنف | D4: اسم المورد | E4: الكمية | F4: السعر | G4: الإجمالي | H4: المدفوع | I4: المتبقي | J4: ملاحظات | N4: كان باقي للعماوي 5040 من شهر 6
A5: 46204 | B5: =IF(A5="","",CHOOSE(WEEKDAY(A5,2),"الاثنين","الثلاثاء","الأربعاء","الخميس","الجمعة","السبت","الأحد")) -> الأربعاء | C5: خامات | D5: العماوي | G5: 16922 | H5: 0 | I5: =IF(OR(G5="",H5=""),"",G5-H5) -> 16922
C6: خامات | D6: العماوي | G6: 920 | H6: 0 | I6: 920
B7: =IF(A7="","",CHOOSE(WEEKDAY(A7,2),"الاثنين","الثلاثاء","الأربعاء","الخميس","الجمعة","السبت","الأحد")) | C7: مياه اوه | D7: العماوي | E7: 50 | F7: 88 | G7: 4400 | H7: 0 | I7: =IF(OR(G7="",H7=""),"",G7-H7) -> 4400
B8: =IF(A8="","",CHOOSE(WEEKDAY(A8,2),"الاثنين","الثلاثاء","الأربعاء","الخميس","الجمعة","السبت","الأحد")) | C8: فاكهة | D8: الهنا | G8: 1481.74 | H8: 1481.74 | I8: =IF(OR(G8="",H8=""),"",G8-H8) -> 0
A9: 46205 | B9: =IF(A9="","",CHOOSE(WEEKDAY(A9,2),"الاثنين","الثلاثاء","الأربعاء","الخميس","الجمعة","السبت","الأحد")) -> الخميس | C9: تابلوهات قهوة | G9: 1220 | H9: 1220 | I9: =IF(OR(G9="",H9=""),"",G9-H9) -> 0
B10: =IF(A10="","",CHOOSE(WEEKDAY(A10,2),"الاثنين","الثلاثاء","الأربعاء","الخميس","الجمعة","السبت","الأحد")) | C10: ثلج | G10: 315 | H10: 315 | I10: =IF(OR(G10="",H10=""),"",G10-H10) -> 0
B11: =IF(A11="","",CHOOSE(WEEKDAY(A11,2),"الاثنين","الثلاثاء","الأربعاء","الخميس","الجمعة","السبت","الأحد")) | C11: ذبادي | G11: 50 | H11: 50 | I11: =IF(OR(G11="",H11=""),"",G11-H11) -> 0
B12: =IF(A12="","",CHOOSE(WEEKDAY(A12,2),"الاثنين","الثلاثاء","الأربعاء","الخميس","الجمعة","السبت","الأحد")) | C12: فاكهة | D12: الهنا | G12: 1065 | H12: 1065 | I12: =IF(OR(G12="",H12=""),"",G12-H12) -> 0
A13: 46206 | B13: الجمعة | C13: فاكهة | D13: الهنا | G13: 1360 | H13: 1360 | I13: =IF(OR(G13="",H13=""),"",G13-H13) -> 0 | J13: مع الدليفري
B14: الجمعة | C14: خامات | D14: العماوي | G14: 8015 | H14: 0 | I14: =IF(OR(G14="",H14=""),"",G14-H14) -> 8015
B15: الجمعة | C15: عصاير مانجة | D15: اللورد | E15: 30 | F15: 200 | G15: 6000 | H15: 6000 | I15: =IF(OR(G15="",H15=""),"",G15-H15) -> 0 | J15: من الخزنة وليست من ايراد اليوم
A16: 46207 | B16: =IF(A16="","",CHOOSE(WEEKDAY(A16,2),"الاثنين","الثلاثاء","الأربعاء","الخميس","الجمعة","السبت","الأحد")) -> السبت | C16: تورته | D16: مدام نهى | G16: 950 | H16: 950 | I16: =IF(OR(G16="",H16=""),"",G16-H16) -> 0
B17: =IF(A17="","",CHOOSE(WEEKDAY(A17,2),"الاثنين","الثلاثاء","الأربعاء","الخميس","الجمعة","السبت","الأحد")) | C17: خامات | D17: العماوي | G17: 13890 | H17: 0 | I17: =IF(OR(G17="",H17=""),"",G17-H17) -> 13890
B18: =IF(A18="","",CHOOSE(WEEKDAY(A18,2),"الاثنين","الثلاثاء","الأربعاء","الخميس","الجمعة","السبت","الأحد")) | C18: فاكهة | D18: الهنا | G18: 1425 | H18: 1425 | I18: =IF(OR(G18="",H18=""),"",G18-H18) -> 0
B19: =IF(A19="","",CHOOSE(WEEKDAY(A19,2),"الاثنين","الثلاثاء","الأربعاء","الخميس","الجمعة","السبت","الأحد")) | C19: طلبات | G19: 1570 | H19: 1570 | I19: =IF(OR(G19="",H19=""),"",G19-H19) -> 0
A20: 46208 | B20: =IF(A20="","",CHOOSE(WEEKDAY(A20,2),"الاثنين","الثلاثاء","الأربعاء","الخميس","الجمعة","السبت","الأحد")) -> الأحد | C20: بسكوت | G20: 2350 | H20: 2350 | I20: =IF(OR(G20="",H20=""),"",G20-H20) -> 0
B21: =IF(A21="","",CHOOSE(WEEKDAY(A21,2),"الاثنين","الثلاثاء","الأربعاء","الخميس","الجمعة","السبت","الأحد")) | C21: طلبات | G21: 515 | H21: 515 | I21: =IF(OR(G21="",H21=""),"",G21-H21) -> 0
A22: 46209 | B22: =IF(A23="","",CHOOSE(WEEKDAY(A23,2),"الاثنين","الثلاثاء","الأربعاء","الخميس","الجمعة","السبت","الأحد")) | C22: فواكه | D22: الهنا | G22: 1940 | H22: 1940 | I22: =IF(OR(G22="",H22=""),"",G22-H22) -> 0
B23: =IF(A24="","",CHOOSE(WEEKDAY(A24,2),"الاثنين","الثلاثاء","الأربعاء","الخميس","الجمعة","السبت","الأحد")) | C23: تشيز كيك | D23: مدام نهى | G23: 400 | H23: 400 | I23: =IF(OR(G23="",H23=""),"",G23-H23) -> 0
B24: =IF(A25="","",CHOOSE(WEEKDAY(A25,2),"الاثنين","الثلاثاء","الأربعاء","الخميس","الجمعة","السبت","الأحد")) | C24: خامات | D24: العماوي | G24: 20218 | H24: 0 | I24: =IF(OR(G24="",H24=""),"",G24-H24) -> 20218
C25: مانجو عصير | D25: اللورد | E25: 30 | F25: 200 | G25: 6000 | H25: 6000
B26: =IF(A27="","",CHOOSE(WEEKDAY(A27,2),"الاثنين","الثلاثاء","الأربعاء","الخميس","الجمعة","السبت","الأحد")) | C26: عصاير مانجة | D26: اللورد | G26: 5800 | H26: 5800 | I26: =IF(OR(G26="",H26=""),"",G26-H26) -> 0 | J26: من الخزنة وليست من ايراد اليوم
B27: =IF(A28="","",CHOOSE(WEEKDAY(A28,2),"الاثنين","الثلاثاء","الأربعاء","الخميس","الجمعة","السبت","الأحد")) -> الثلاثاء | C27: تورته | D27: مدام نهى | G27: 350 | H27: 350 | I27: =IF(OR(G27="",H27=""),"",G27-H27) -> 0 | L27: اجمالي المشتريات
A28: 46210 | B28: =IF(A29="","",CHOOSE(WEEKDAY(A29,2),"الاثنين","الثلاثاء","الأربعاء","الخميس","الجمعة","السبت","الأحد")) -> الأربعاء | C28: كرتونة مياه | E28: 10 | G28: 1000 | I28: =IF(OR(G28="",H28=""),"",G28-H28)
A29: 46211 | B29: =IF(A30="","",CHOOSE(WEEKDAY(A30,2),"الاثنين","الثلاثاء","الأربعاء","الخميس","الجمعة","السبت","الأحد")) | C29: فواكه | D29: الهنا | G29: 205 | H29: 205 | I29: =IF(OR(G29="",H29=""),"",G29-H29) -> 0 | L29: =SUM(G5:G240) -> 178985.94
B30: =IF(A31="","",CHOOSE(WEEKDAY(A31,2),"الاثنين","الثلاثاء","الأربعاء","الخميس","الجمعة","السبت","الأحد")) | C30: كرتونة مياه | E30: 50 | G30: 4400 | H30: 4400 | I30: =IF(OR(G30="",H30=""),"",G30-H30) -> 0
B31: =IF(A32="","",CHOOSE(WEEKDAY(A32,2),"الاثنين","الثلاثاء","الأربعاء","الخميس","الجمعة","السبت","الأحد")) -> الخميس | C31: طلبات | G31: 270 | H31: 270 | I31: =IF(OR(G31="",H31=""),"",G31-H31) -> 0
A32: 46212 | B32: =IF(A33="","",CHOOSE(WEEKDAY(A33,2),"الاثنين","الثلاثاء","الأربعاء","الخميس","الجمعة","السبت","الأحد")) | C32: خامات | D32: العماوي | G32: 7400 | I32: =IF(OR(G32="",H32=""),"",G32-H32)
B33: =IF(A34="","",CHOOSE(WEEKDAY(A34,2),"الاثنين","الثلاثاء","الأربعاء","الخميس","الجمعة","السبت","الأحد")) | C33: مكسرات | G33: 2000 | H33: 2000 | I33: =IF(OR(G33="",H33=""),"",G33-H33) -> 0
B34: =IF(A35="","",CHOOSE(WEEKDAY(A35,2),"الاثنين","الثلاثاء","الأربعاء","الخميس","الجمعة","السبت","الأحد")) | C34: فاكهة | D34: الهنا | G34: 1115 | H34: 1115 | I34: =IF(OR(G34="",H34=""),"",G34-H34) -> 0
B35: =IF(A36="","",CHOOSE(WEEKDAY(A36,2),"الاثنين","الثلاثاء","الأربعاء","الخميس","الجمعة","السبت","الأحد")) | C35: خامات | D35: العماوي | G35: 1830 | H35: 0 | I35: =IF(OR(G35="",H35=""),"",G35-H35) -> 1830
B36: =IF(A37="","",CHOOSE(WEEKDAY(A37,2),"الاثنين","الثلاثاء","الأربعاء","الخميس","الجمعة","السبت","الأحد")) | C36: خامات | D36: العماوي | G36: 4990 | H36: 0 | I36: =IF(OR(G36="",H36=""),"",G36-H36) -> 4990 | J36: يوجد مرتجع بقيمة 270
B37: =IF(A38="","",CHOOSE(WEEKDAY(A38,2),"الاثنين","الثلاثاء","الأربعاء","الخميس","الجمعة","السبت","الأحد")) | C37: خامات | D37: العماوي | G37: 1170 | H37: 0 | I37: =IF(OR(G37="",H37=""),"",G37-H37) -> 1170
B38: =IF(A39="","",CHOOSE(WEEKDAY(A39,2),"الاثنين","الثلاثاء","الأربعاء","الخميس","الجمعة","السبت","الأحد")) -> الجمعة | C38: فواكه | D38: الهنا | G38: 550 | H38: 550 | I38: =IF(OR(G38="",H38=""),"",G38-H38) -> 0
A39: 46213 | B39: =IF(A40="","",CHOOSE(WEEKDAY(A40,2),"الاثنين","الثلاثاء","الأربعاء","الخميس","الجمعة","السبت","الأحد")) -> السبت | C39: خامات | D39: العماوي | G39: 6935 | H39: 6935 | I39: =IF(OR(G39="",H39=""),"",G39-H39) -> 0 | J39: تم الدفع انستا باي و خصمهم من ايرادات اليوم
A40: 46214 | B40: =IF(A41="","",CHOOSE(WEEKDAY(A41,2),"الاثنين","الثلاثاء","الأربعاء","الخميس","الجمعة","السبت","الأحد")) | C40: فواكه | D40: الهنا | G40: 630 | H40: 630 | I40: =IF(OR(G40="",H40=""),"",G40-H40) -> 0
B41: =IF(A42="","",CHOOSE(WEEKDAY(A42,2),"الاثنين","الثلاثاء","الأربعاء","الخميس","الجمعة","السبت","الأحد")) -> الأحد | C41: فواكه | D41: الهنا | G41: 900 | H41: 900 | I41: =IF(OR(G41="",H41=""),"",G41-H41) -> 0
A42: 46215 | B42: =IF(A43="","",CHOOSE(WEEKDAY(A43,2),"الاثنين","الثلاثاء","الأربعاء","الخميس","الجمعة","السبت","الأحد")) | C42: خامات | D42: العماوي | G42: 7000 | H42: 7000 | I42: =IF(OR(G42="",H42=""),"",G42-H42) -> 0
...

Sheet تقفيلة اليوم
A2: سجل التقفيلات اليومية -يوليو 2026
T3: مصروفات من الخزنة
A5: التاريخ | B5: اليوم | C5: كاش | D5: انستا | E5: فودافون كاش | F5: المشتريات | G5: المصروفات النثرية | H5: السلفة | I5: سداد الموردين(العماوي) | J5: رواتب | K5: مسحوبات المالك | L5: مكافئة | M5: اجل | N5: الاجمالي | O5: ملاحظات | T5: ملاحظات | U5: المبلغ | V5: البيان | W5: التاريخ
A6: 46204 | B6: =CHOOSE(WEEKDAY(A6,2),"الاثنين","الثلاثاء","الأربعاء","الخميس","الجمعة","السبت","الأحد") -> الأربعاء | C6: =4700+2927 -> 7627 | D6: =65+80+315+775+180+295+65+425 -> 2200 | F6: 1481.74 | G6: =1910+50 -> 1960 | H6: 1110 | J6: 3000 | L6: 200 | M6: 1220 | N6: =SUM(C6:M6) -> 18798.74 | O6: يوجد زياده 80 جنيه / تم سداد اجل بقيمة 1220 جنيه من ح طارق / | U6: 33000 | V6: سداد فاتوؤة العماوي | W6: 46214
A7: 46205 | B7: =CHOOSE(WEEKDAY(A7,2),"الاثنين","الثلاثاء","الأربعاء","الخميس","الجمعة","السبت","الأحد") -> الخميس | C7: =1175+1173 -> 2348 | D7: =100+175+60+100+100 -> 535 | F7: =1220+315+1065+50 -> 2650 | G7: =800+40+200+150+2250 -> 3440 | H7: =600+25+50+10+100+100+20+10+200 -> 1115 | I7: 10000 | N7: =SUM(C7:M7) -> 20088 | O7: يوجد زيادة 78 جنيه
A8: 46206 | B8: =CHOOSE(WEEKDAY(A8,2),"الاثنين","الثلاثاء","الأربعاء","الخميس","الجمعة","السبت","الأحد") -> الجمعة | C8: 3000 | D8: 145 | E8: 220 | F8: =1360 -> 1360 | G8: =8000+570+2000+750 -> 11320 | H8: =30+200+100+200+50+10+200+10+10+30+30 -> 870 | I8: 10000 | N8: =SUM(C8:M8) -> 26915 | O8: يوجد زياد 842 / ماتش مصر و اتسراليا
A9: 46207 | B9: =CHOOSE(WEEKDAY(A9,2),"الاثنين","الثلاثاء","الأربعاء","الخميس","الجمعة","السبت","الأحد") -> السبت | C9: 1955 | D9: 125 | E9: =180+915+395 -> 1490 | F9: =950+1570+1425 -> 3945 | G9: 150 | H9: =25+25+100+125+125+125+100+300+350+200+125+150 -> 1750 | I9: 5000 | J9: 800 | N9: =SUM(C9:J9) -> 15215 | O9: يوجد زيادة 246 جنيه محمد صلاح 800
A10: 46208 | B10: =CHOOSE(WEEKDAY(A10,2),"الاثنين","الثلاثاء","الأربعاء","الخميس","الجمعة","السبت","الأحد") -> الأحد | C10: 1275 | D10: 280 | E10: 430 | F10: =515+2350 -> 2865 | H10: 1110 | J10: 12370 | N10: =SUM(C10:J10) -> 18330
A11: 46209 | B11: =CHOOSE(WEEKDAY(A11,2),"الاثنين","الثلاثاء","الأربعاء","الخميس","الجمعة","السبت","الأحد") -> الاثنين | C11: =2200+9000 -> 11200 | D11: 625 | F11: =2940+400 -> 3340 | G11: =175+150 -> 325 | H11: =960+195 -> 1155 | J11: 3000 | N11: =SUM(C11:J11) -> 19645
A12: 46210 | B12: =CHOOSE(WEEKDAY(A12,2),"الاثنين","الثلاثاء","الأربعاء","الخميس","الجمعة","السبت","الأحد") -> الثلاثاء | C12: 9863 | D12: 705 | E12: 475 | F12: 350 | G12: 14695 | H12: 200 | J12: 3000 | N12: =SUM(C12:J12) -> 29288 | O12: ماتش مصر و الارجنتين
A13: 46211 | B13: =CHOOSE(WEEKDAY(A13,2),"الاثنين","الثلاثاء","الأربعاء","الخميس","الجمعة","السبت","الأحد") -> الأربعاء | C13: 3253 | D13: 550 | E13: 50 | F13: 5605 | G13: 280 | H13: =5800-5470 -> 330 | J13: =4470+1000 -> 5470 | N13: =SUM(C13:J13) -> 15538
A14: 46212 | B14: =CHOOSE(WEEKDAY(A14,2),"الاثنين","الثلاثاء","الأربعاء","الخميس","الجمعة","السبت","الأحد") -> الخميس | C14: 1540 | D14: 985 | E14: 690 | F14: 10785 | G14: 220 | H14: 2240 | N14: =SUM(C14:H14) -> 16460 | O14: يوجد زيادة 38 جنبيه
A15: 46213 | B15: =CHOOSE(WEEKDAY(A15,2),"الاثنين","الثلاثاء","الأربعاء","الخميس","الجمعة","السبت","الأحد") -> الجمعة | C15: 190 | E15: =40+335 -> 375 | F15: =550 -> 550 | G15: 80 | H15: 95 | I15: 10000 | N15: =SUM(C15:I15) -> 11290 | O15: تغيير الورديه من 8 الي 12
A16: 46214 | B16: =CHOOSE(WEEKDAY(A16,2),"الاثنين","الثلاثاء","الأربعاء","الخميس","الجمعة","السبت","الأحد") -> السبت | C16: 4650 | D16: 150 | E16: 580 | F16: =630 -> 630 | G16: 150 | H16: =850 -> 850 | I16: 6935 | J16: 2750 | N16: =SUM(C16:J16) -> 16695
A17: 46215 | B17: =CHOOSE(WEEKDAY(A17,2),"الاثنين","الثلاثاء","الأربعاء","الخميس","الجمعة","السبت","الأحد") -> الأحد | C17: 4201 | D17: 205 | E17: 400 | F17: =900 -> 900 | G17: =70+500 -> 570 | H17: =3968-1500 -> 2468 | I17: 7000 | J17: 1500 | N17: =SUM(C17:L17) -> 17244
A18: 46216 | B18: =CHOOSE(WEEKDAY(A18,2),"الاثنين","الثلاثاء","الأربعاء","الخميس","الجمعة","السبت","الأحد") -> الاثنين | C18: 5405 | D18: 300 | E18: 955 | F18: =7225-40 -> 7185 | G18: =500+40 -> 540 | H18: 3620 | J18: =1660+3000+500 -> 5160 | N18: =SUM(C18:J18) -> 23165
A19: 46217 | B19: =CHOOSE(WEEKDAY(A19,2),"الاثنين","الثلاثاء","الأربعاء","الخميس","الجمعة","السبت","الأحد") -> الثلاثاء | C19: 7164 | D19: 270 | E19: 780 | F19: 3700 | G19: 150 | H19: =5172-3792 -> 1380 | J19: 3000 | K19: =360+432 -> 792 | N19: =SUM(C19:K19) -> 17236 | O19: يوجد زياده 150 جنيه
A20: 46218 | B20: =CHOOSE(WEEKDAY(A20,2),"الاثنين","الثلاثاء","الأربعاء","الخميس","الجمعة","السبت","الأحد") -> الأربعاء | C20: 4255 | D20: 585 | E20: 1020 | F20: 8197 | G20: =200+30+50+70 -> 350 | H20: =5857-100 -> 5757 | L20: 100 | N20: =SUM(C20:L20) -> 20264 | O20: يوجد زيادة 72 جنيه
A21: 46219 | B21: =CHOOSE(WEEKDAY(A21,2),"الاثنين","الثلاثاء","الأربعاء","الخميس","الجمعة","السبت","الأحد") -> الخميس | C21: 4120 | D21: 170 | E21: 345 | F21: =SUM('المشتريات اليومية'!G54:G56) -> 4780 | G21: =SUM('المصروفات النثرية'!D45:D46) -> 250 | H21: =SUM('سلف الموظفين'!C143:C154) -> 3880 | N21: =SUM(C21:H21) -> 13545
A22: 46220 | B22: =CHOOSE(WEEKDAY(A22,2),"الاثنين","الثلاثاء","الأربعاء","الخميس","الجمعة","السبت","الأحد") -> الجمعة | C22: 0 | D22: 658 | E22: 100 | F22: =3310-30 -> 3280 | G22: 30 | H22: 2912 | I22: 6832 | K22: =48+576 -> 624 | N22: =SUM(C22:K22) -> 14436 | O22: تم سداد الي مستر احمد عاشور مبلغ 6832 نظير سداد فاتورة العماوي و باقي ليه 968
A23: 46221 | B23: =CHOOSE(WEEKDAY(A23,2),"الاثنين","الثلاثاء","الأربعاء","الخميس","الجمعة","السبت","الأحد") -> السبت | C23: 3183 | D23: 250 | E23: 1775 | F23: =5055+210 -> 5265 | H23: 5460 | N23: =SUM(C23:H23) -> 15933
A24: 46222 | B24: =CHOOSE(WEEKDAY(A24,2),"الاثنين","الثلاثاء","الأربعاء","الخميس","الجمعة","السبت","الأحد") -> الأحد | C24: 20782 | D24: 590 | E24: 170 | F24: 90 | G24: =150+200+120 -> 470 | H24: 1306 | N24: =SUM(C24:H24) -> 23408 | O24: عجز في 24 جنيه
A25: 46223 | B25: =CHOOSE(WEEKDAY(A25,2),"الاثنين","الثلاثاء","الأربعاء","الخميس","الجمعة","السبت","الأحد") -> الاثنين | N25: =SUM(C25:H25) -> 0
A26: 46224 | B26: =CHOOSE(WEEKDAY(A26,2),"الاثنين","الثلاثاء","الأربعاء","الخميس","الجمعة","السبت","الأحد") -> الثلاثاء | N26: =SUM(C26:H26) -> 0
A27: 46225 | B27: =CHOOSE(WEEKDAY(A27,2),"الاثنين","الثلاثاء","الأربعاء","الخميس","الجمعة","السبت","الأحد") -> الأربعاء | N27: =SUM(C27:H27) -> 0
A28: 46226 | B28: =CHOOSE(WEEKDAY(A28,2),"الاثنين","الثلاثاء","الأربعاء","الخميس","الجمعة","السبت","الأحد") -> الخميس | N28: =SUM(C28:H28) -> 0
A29: 46227 | B29: =CHOOSE(WEEKDAY(A29,2),"الاثنين","الثلاثاء","الأربعاء","الخميس","الجمعة","السبت","الأحد") -> الجمعة | N29: =SUM(C29:H29) -> 0
A30: 46228 | B30: =CHOOSE(WEEKDAY(A30,2),"الاثنين","الثلاثاء","الأربعاء","الخميس","الجمعة","السبت","الأحد") -> السبت | N30: =SUM(C30:H30) -> 0
A31: 46229 | B31: =CHOOSE(WEEKDAY(A31,2),"الاثنين","الثلاثاء","الأربعاء","الخميس","الجمعة","السبت","الأحد") -> الأحد | N31: =SUM(C31:H31) -> 0
A32: 46230 | B32: =CHOOSE(WEEKDAY(A32,2),"الاثنين","الثلاثاء","الأربعاء","الخميس","الجمعة","السبت","الأحد") -> الاثنين | N32: =SUM(C32:H32) -> 0
A33: 46231 | B33: =CHOOSE(WEEKDAY(A33,2),"الاثنين","الثلاثاء","الأربعاء","الخميس","الجمعة","السبت","الأحد") -> الثلاثاء | N33: =SUM(C33:H33) -> 0
A34: 46232 | B34: =CHOOSE(WEEKDAY(A34,2),"الاثنين","الثلاثاء","الأربعاء","الخميس","الجمعة","السبت","الأحد") -> الأربعاء | N34: =SUM(C34:H34) -> 0
A35: 46233 | B35: =CHOOSE(WEEKDAY(A35,2),"الاثنين","الثلاثاء","الأربعاء","الخميس","الجمعة","السبت","الأحد") -> الخميس | N35: =SUM(C35:H35) -> 0
A36: 46234 | B36: =CHOOSE(WEEKDAY(A36,2),"الاثنين","الثلاثاء","الأربعاء","الخميس","الجمعة","السبت","الأحد") -> الجمعة | N36: =SUM(C36:H36) -> 0
A37: الاجمالي | N37: =SUM(N6:N36) -> 353493.74

Sheet المصروفات النثرية
A2: سجل المصروفات النثرية - يوليو 2026
A4: التاريخ | B4: الفئة | C4: المبلغ | D4: المبلغ المدفوع | E4: المبلغ المتبقى | F4: ملاحظات
A5: 46204 | B5: كهرباء | C5: 1530 | D5: 1530 | E5: =IF(OR(C5="",D5=""),"",C5-D5) -> 0
A6: 46204 | B6: دليفري العماوي | C6: 150 | D6: 150 | E6: =IF(OR(C6="",D6=""),"",C6-D6) -> 0
A7: 46204 | B7: دليفري العماوي | C7: 80 | D7: 80 | E7: =IF(OR(C7="",D7=""),"",C7-D7) -> 0
A8: 46204 | B8: دليفري الهنا | C8: 50 | D8: 50 | E8: 0
A9: 46204 | B9: مياه توصيلة | C9: 150 | D9: 150 | E9: =IF(OR(C9="",D9=""),"",C9-D9) -> 0
A10: 46205 | B10: شتلة | C10: 200 | D10: 200 | E10: =IF(OR(C10="",D10=""),"",C10-D10) -> 0
A11: 46205 | B11: دليفري الهنا | C11: 150 | D11: 150 | E11: =IF(OR(C11="",D11=""),"",C11-D11) -> 0
A12: 46205 | B12: صيانة تلاجة | C12: 800 | D12: 800 | E12: =IF(OR(C12="",D12=""),"",C12-D12) -> 0
A13: 46205 | B13: بنزين للماكينة النجيل | C13: 40 | D13: 40 | E13: =IF(OR(C13="",D13=""),"",C13-D13) -> 0
A14: 46205 | B14: تكملة فلوس الكراسي | C14: 2250 | D14: 2250 | E14: =IF(OR(C14="",D14=""),"",C14-D14) -> 0
A15: 46206 | B15: صيانة تلاجة | C15: 750 | D15: 750 | E15: =IF(OR(C15="",D15=""),"",C15-D15) -> 0
A16: 46206 | B16: تلج | C16: 570 | D16: 570 | E16: =IF(OR(C16="",D16=""),"",C16-D16) -> 0
A17: 46206 | B17: انترنت | C17: 2000 | D17: 2000 | E17: =IF(OR(C17="",D17=""),"",C17-D17) -> 0
A18: 46206 | B18: فراشة | C18: 8000 | D18: 8000 | E18: =IF(OR(C18="",D18=""),"",C18-D18) -> 0
A19: 46206 | B19: درون | C19: 1500 | D19: 1500 | E19: =IF(OR(C19="",D19=""),"",C19-D19) -> 0 | F19: ماتش مصر و استراليا / من الخزنة وليس من الايرادات
A20: 46206 | B20: توصيل تلاجات | C20: 1000 | D20: 1000 | E20: =IF(OR(C20="",D20=""),"",C20-D20) -> 0 | F20: من الخزنة و ليس من ايرادات اليوم
A21: 46207 | B21: دليفري | C21: 150 | D21: 150 | E21: =IF(OR(C21="",D21=""),"",C21-D21) -> 0 | H21: اجمالي المصروفات
A22: 46209 | B22: بريل | C22: 175 | D22: 175 | E22: =IF(OR(C22="",D22=""),"",C22-D22) -> 0
A23: 46209 | B23: دليفري | C23: 150 | D23: 150 | E23: =IF(OR(C23="",D23=""),"",C23-D23) -> 0
A24: 46210 | B24: درون | C24: 1500 | D24: 1500 | E24: 0 | F24: ماتش مصر و الارجنتين
A25: 46210 | B25: تلج | C25: 465 | D25: 465 | E25: =IF(OR(C25="",D25=""),"",C25-D25) -> 0
A26: 46210 | B26: كاميرا فوتوجرافر | C26: 1500 | D26: 1500 | E26: =IF(OR(C26="",D26=""),"",C26-D26) -> 0 | F26: ماتش مصر و الارجنتين
A27: 46210 | B27: فرش للماتش | C27: 11000 | D27: 11000 | E27: =IF(OR(C27="",D27=""),"",C27-D27) -> 0 | F27: ماتش مصر و الارجنتين
A28: 46210 | B28: دليفري | C28: 230 | D28: 230 | E28: =IF(OR(C28="",D28=""),"",C28-D28) -> 0
A29: 46211 | B29: دليفري | C29: 30 | D29: 30 | E29: =IF(OR(C29="",D29=""),"",C29-D29) -> 0
A30: 46211 | B30: محمد هيبلغني بيهم | C30: 250 | D30: 250 | E30: =IF(OR(C30="",D30=""),"",C30-D30) -> 0
A31: 46212 | B31: دليفري العماوي | C31: 80 | D31: 80 | E31: =IF(OR(C31="",D31=""),"",C31-D31) -> 0
A32: 46212 | B32: دليفري الهنا | C32: 70 | D32: 70 | E32: =IF(OR(C32="",D32=""),"",C32-D32) -> 0
A33: 46212 | B33: دليفري العماوي | C33: 70 | D33: 70 | E33: =IF(OR(C33="",D33=""),"",C33-D33) -> 0
A34: 46213 | B34: دليفري الهنا | C34: 80 | D34: 80 | E34: =IF(OR(C34="",D34=""),"",C34-D34) -> 0
A35: 46214 | B35: دليفري | C35: 150 | D35: 150 | E35: =IF(OR(C35="",D35=""),"",C35-D35) -> 0
A36: 46215 | B36: دليفري الهنا | C36: 70 | D36: 70 | E36: =IF(OR(C36="",D36=""),"",C36-D36) -> 0
A37: 46215 | B37: تحت حساب اصلاح مكنة النجيلة | C37: 500 | D37: 500 | E37: 0
A38: 46216 | B38: بنزين و زيت للمكنة | C38: 500 | D38: 500 | E38: 0
A39: 46216 | B39: دليفري الهنا | C39: 40 | D39: 40 | E39: 0
A40: 46217 | B40: دليفري الثلج | C40: 150 | D40: 150 | E40: 0
A41: 46218 | B41: مسامير | C41: 30 | D41: 30 | E41: 0
A42: 46218 | B42: دليفري الهنا | C42: 50 | D42: 50 | E42: 0
...

Sheet سلف الموظفين
A2: سلف الموظفين | H2: خصومات الموظفين
A4: التاريخ | B4: اسم الموظف | C4: المبلغ | D4: ملاحظات | H4: التاريخ | I4: الخصومات | K4: اسم الموظف
A5: 46204 | B5: عبد الله محمد عبد المنعم | C5: 200 | E5: =SUM(C5:C15) -> 1110 | H5: 46204 | I5: خصم نصف يوم | K5: محمد رافت
B6: احمد ايمن رجب | C6: 200 | H6: 46204 | I6: خصم نصف يوم | K6: محمود محمد
B7: فارس | C7: 60 | H7: 46206 | I7: خصم ربع يوم | K7: رياض
B8: محمد صبري محمد | C8: 100 | H8: 46206 | I8: خصم ربع يوم | K8: محمد عزت
B9: اسلام | C9: 100 | H9: 46206 | I9: خصم ربع يوم | K9: عبد الله
B10: عبد الله الغذالي | C10: 100 | H10: 46209 | I10: ربع يوم | K10: محمد رافت | P10: =SUM(C5:C15) -> 1110
B11: فهمي | C11: 100 | H11: 46209 | I11: 3 ايام | K11: رياض | P11: =SUM(C16:C24) -> 1115
B12: ادم | H12: 46209 | I12: ايام3 | K12: عبد الله
B13: احمد هشهش | C13: 100 | H13: 46211 | I13: نص يوم | K13: محمد صبري
B14: رياض حامد رياض عطية | C14: 50 | H14: 46211 | I14: نص يوم | K14: فارس
B15: محمد عزت | C15: 100 | H15: 46211 | I15: تص يوم | K15: عبد الرحمن
A16: 46205 | E16: =SUM(C17:C24) -> 1115 | H16: 46212 | I16: نصف يوم | K16: ادم
B17: محمود محمد | C17: 200 | H17: 46212 | I17: تصف يوم | K17: فهمي
B18: محمد صبري محمد | C18: 100 | H18: 46220 | I18: خصم نصف يوم | K18: سيف فخري
B19: رياض حامد رياض عطية | C19: 625 | H19: 46220 | I19: خصم نصف يوم | K19: احمد الجوهري
B20: فهمي | C20: 50 | H20: 46220 | I20: خصم ربع يوم | K20: محمد صبري
B21: احمد هش هش | C21: 100 | D21: بدل موصلات | H21: 46221 | I21: خصم يومين | K21: احمد الطيب
B22: عمار محمد صبحي عبد الفتاح | C22: 10 | I22: خصم يوم | K22: محمد صبري
B23: عبد الله الغذالي | C23: 10 | H23: 46222 | I23: خصم نصف يوم | K23: رضا
B24: سيف عصام طايل | C24: 20
A25: 46206 | B25: عيد نوح عيد نوح صالح | C25: 200 | E25: =SUM(C25:C35) -> 870
B26: محمد رافت | C26: 30
B27: محمد صلاح | C27: 200
B28: احمد هشهش | C28: 100
B29: فهمي | C29: 200
B30: عبد الله محمد عبد المنعم | C30: 50
B31: عبد الله الغذالي | C31: 10
B32: محمود محمد صبحي | C32: 10
B33: محمد عزت | C33: 10
B34: محمد صبري محمد | C34: 30
B35: عبد الله محمد عبد المنعم | C35: 30
A36: 46207 | B36: فهمي | C36: 150
B37: عبد الله الغذالي | C37: 125
B38: ادم ياسر محمد | C38: 200
B39: محمد عزت | C39: 350
B40: محمد صبحي | C40: 300
B41: سيف عصام طايل | C41: 100
B42: محمد صبري محمد | C42: 125
...

Sheet الإيرادات اليومية
A1: جدول الإيرادات اليومية
A3: التاريخ | B3: اليوم | C3: كاش | D3: فودافون كاش | E3: انستا باي | F3: صافي اليوم | G3: ملاحظات | P3: التاريخ | Q3: اليوم | R3: كاش | S3: انستا باي | T3: صافي اليوم
A4: 46204 | B4: =CHOOSE(WEEKDAY(A4,2),"الاثنين","الثلاثاء","الأربعاء","الخميس","الجمعة","السبت","الأحد") -> الأربعاء | C4: =4700+2927 -> 7627 | E4: =65+80+315+775+180+295+65+425 -> 2200 | F4: =IF(SUM(C4:E4)=0,0,SUM(C4:E4)) -> 9827 | P4: 46204 | Q4: =CHOOSE(WEEKDAY(P4,2),"الاثنين","الثلاثاء","الأربعاء","الخميس","الجمعة","السبت","الأحد") -> الأربعاء | R4: =4700+2927 -> 7627 | S4: - | T4: =IF(SUM(R4:S4)=0,0,SUM(R4:S4)) -> 7627
A5: 46205 | B5: =CHOOSE(WEEKDAY(A5,2),"الاثنين","الثلاثاء","الأربعاء","الخميس","الجمعة","السبت","الأحد") -> الخميس | C5: 2348 | E5: 535 | F5: =IF(SUM(C5:E5)=0,0,SUM(C5:E5)) -> 2883 | P5: 46205 | Q5: =CHOOSE(WEEKDAY(P5,2),"الاثنين","الثلاثاء","الأربعاء","الخميس","الجمعة","السبت","الأحد") -> الخميس | R5: 2348 | S5: 100 | T5: =IF(SUM(R5:S5)=0,0,SUM(R5:S5)) -> 2448
A6: 46206 | B6: =CHOOSE(WEEKDAY(A6,2),"الاثنين","الثلاثاء","الأربعاء","الخميس","الجمعة","السبت","الأحد") -> الجمعة | C6: 3000 | D6: 145 | E6: 220 | F6: =IF(SUM(C6:E6)=0,0,SUM(C6:E6)) -> 3365 | P6: 46206 | Q6: =CHOOSE(WEEKDAY(P6,2),"الاثنين","الثلاثاء","الأربعاء","الخميس","الجمعة","السبت","الأحد") -> الجمعة | R6: 3000 | S6: 145 | T6: =IF(SUM(R6:S6)=0,0,SUM(R6:S6)) -> 3145
A7: 46207 | B7: =CHOOSE(WEEKDAY(A7,2),"الاثنين","الثلاثاء","الأربعاء","الخميس","الجمعة","السبت","الأحد") -> السبت | C7: 1955 | D7: 1490 | E7: 125 | F7: =IF(SUM(C7:E7)=0,0,SUM(C7:E7)) -> 3570 | P7: 46207 | Q7: =CHOOSE(WEEKDAY(P7,2),"الاثنين","الثلاثاء","الأربعاء","الخميس","الجمعة","السبت","الأحد") -> السبت | R7: 1955 | S7: 125 | T7: =IF(SUM(R7:S7)=0,0,SUM(R7:S7)) -> 2080
A8: 46208 | B8: =CHOOSE(WEEKDAY(A8,2),"الاثنين","الثلاثاء","الأربعاء","الخميس","الجمعة","السبت","الأحد") -> الأحد | C8: 1275 | D8: 430 | E8: 280 | F8: =IF(SUM(C8:E8)=0,0,SUM(C8:E8)) -> 1985 | P8: 46208 | Q8: =CHOOSE(WEEKDAY(P8,2),"الاثنين","الثلاثاء","الأربعاء","الخميس","الجمعة","السبت","الأحد") -> الأحد | R8: 1275 | S8: 280 | T8: =IF(SUM(R8:S8)=0,0,SUM(R8:S8)) -> 1555
A9: 46209 | B9: =CHOOSE(WEEKDAY(A9,2),"الاثنين","الثلاثاء","الأربعاء","الخميس","الجمعة","السبت","الأحد") -> الاثنين | C9: =2200+9000 -> 11200 | E9: 625 | F9: =IF(SUM(C9:E9)=0,0,SUM(C9:E9)) -> 11825 | P9: 46209 | Q9: =CHOOSE(WEEKDAY(P9,2),"الاثنين","الثلاثاء","الأربعاء","الخميس","الجمعة","السبت","الأحد") -> الاثنين | R9: =2200+9000 -> 11200 | S9: 625 | T9: =IF(SUM(R9:S9)=0,0,SUM(R9:S9)) -> 11825
A10: 46210 | B10: =CHOOSE(WEEKDAY(A10,2),"الاثنين","الثلاثاء","الأربعاء","الخميس","الجمعة","السبت","الأحد") -> الثلاثاء | C10: 9863 | D10: 705 | E10: 475 | F10: =IF(SUM(C10:E10)=0,0,SUM(C10:E10)) -> 11043 | P10: 46210 | Q10: =CHOOSE(WEEKDAY(P10,2),"الاثنين","الثلاثاء","الأربعاء","الخميس","الجمعة","السبت","الأحد") -> الثلاثاء | R10: 9863 | S10: 705 | T10: =IF(SUM(R10:S10)=0,0,SUM(R10:S10)) -> 10568
A11: 46211 | B11: =CHOOSE(WEEKDAY(A11,2),"الاثنين","الثلاثاء","الأربعاء","الخميس","الجمعة","السبت","الأحد") -> الأربعاء | C11: 3253 | D11: 550 | E11: 50 | F11: =IF(SUM(C11:E11)=0,0,SUM(C11:E11)) -> 3853 | P11: 46211 | Q11: =CHOOSE(WEEKDAY(P11,2),"الاثنين","الثلاثاء","الأربعاء","الخميس","الجمعة","السبت","الأحد") -> الأربعاء | R11: 3253 | S11: 550 | T11: =IF(SUM(R11:S11)=0,0,SUM(R11:S11)) -> 3803
A12: 46212 | B12: =CHOOSE(WEEKDAY(A12,2),"الاثنين","الثلاثاء","الأربعاء","الخميس","الجمعة","السبت","الأحد") -> الخميس | C12: 1540 | D12: 690 | E12: 985 | F12: =IF(SUM(C12:E12)=0,0,SUM(C12:E12)) -> 3215 | P12: 46212 | Q12: =CHOOSE(WEEKDAY(P12,2),"الاثنين","الثلاثاء","الأربعاء","الخميس","الجمعة","السبت","الأحد") -> الخميس | R12: 1540 | S12: 985 | T12: =IF(SUM(R12:S12)=0,0,SUM(R12:S12)) -> 2525
A13: 46213 | B13: =CHOOSE(WEEKDAY(A13,2),"الاثنين","الثلاثاء","الأربعاء","الخميس","الجمعة","السبت","الأحد") -> الجمعة | C13: 190 | D13: 375 | F13: =IF(SUM(C13:E13)=0,0,SUM(C13:E13)) -> 565 | J13: =SUM(F4:F16) -> 68977 | P13: 46213 | Q13: =CHOOSE(WEEKDAY(P13,2),"الاثنين","الثلاثاء","الأربعاء","الخميس","الجمعة","السبت","الأحد") -> الجمعة | R13: 190 | T13: =IF(SUM(R13:S13)=0,0,SUM(R13:S13)) -> 190
A14: 46214 | B14: =CHOOSE(WEEKDAY(A14,2),"الاثنين","الثلاثاء","الأربعاء","الخميس","الجمعة","السبت","الأحد") -> السبت | C14: 4650 | D14: 580 | E14: 150 | F14: =IF(SUM(C14:E14)=0,0,SUM(C14:E14)) -> 5380 | P14: 46214 | Q14: =CHOOSE(WEEKDAY(P14,2),"الاثنين","الثلاثاء","الأربعاء","الخميس","الجمعة","السبت","الأحد") -> السبت | R14: 4650 | S14: 150 | T14: =IF(SUM(R14:S14)=0,0,SUM(R14:S14)) -> 4800
A15: 46215 | B15: =CHOOSE(WEEKDAY(A15,2),"الاثنين","الثلاثاء","الأربعاء","الخميس","الجمعة","السبت","الأحد") -> الأحد | C15: 4201 | D15: 400 | E15: 205 | F15: =IF(SUM(C15:E15)=0,0,SUM(C15:E15)) -> 4806 | P15: 46215 | Q15: =CHOOSE(WEEKDAY(P15,2),"الاثنين","الثلاثاء","الأربعاء","الخميس","الجمعة","السبت","الأحد") -> الأحد | R15: 4201 | S15: 205 | T15: =IF(SUM(R15:S15)=0,0,SUM(R15:S15)) -> 4406
A16: 46216 | B16: =CHOOSE(WEEKDAY(A16,2),"الاثنين","الثلاثاء","الأربعاء","الخميس","الجمعة","السبت","الأحد") -> الاثنين | C16: 5405 | D16: 955 | E16: 300 | F16: =IF(SUM(C16:E16)=0,0,SUM(C16:E16)) -> 6660 | P16: 46216 | Q16: =CHOOSE(WEEKDAY(P16,2),"الاثنين","الثلاثاء","الأربعاء","الخميس","الجمعة","السبت","الأحد") -> الاثنين | R16: 5405 | S16: 300 | T16: =IF(SUM(R16:S16)=0,0,SUM(R16:S16)) -> 5705
A17: 46217 | B17: =CHOOSE(WEEKDAY(A17,2),"الاثنين","الثلاثاء","الأربعاء","الخميس","الجمعة","السبت","الأحد") -> الثلاثاء | C17: 7164 | D17: =150+630 -> 780 | E17: =40+175+55 -> 270 | F17: =IF(SUM(C17:E17)=0,0,SUM(C17:E17)) -> 8214 | P17: الاجمالي | Q17: - | R17: =SUM(R4:R16) -> 56507 | S17: =SUM(S5:S16) -> 4170 | T17: =SUM(T4:T16) -> 60677
A18: 46218 | B18: =CHOOSE(WEEKDAY(A18,2),"الاثنين","الثلاثاء","الأربعاء","الخميس","الجمعة","السبت","الأحد") -> الأربعاء | C18: 4255 | D18: 1020 | E18: 585 | F18: =IF(SUM(C18:E18)=0,0,SUM(C18:E18)) -> 5860
A19: 46219 | B19: =CHOOSE(WEEKDAY(A19,2),"الاثنين","الثلاثاء","الأربعاء","الخميس","الجمعة","السبت","الأحد") -> الخميس | F19: =IF(SUM(C19:E19)=0,0,SUM(C19:E19)) -> 0
A20: 46220 | B20: =CHOOSE(WEEKDAY(A20,2),"الاثنين","الثلاثاء","الأربعاء","الخميس","الجمعة","السبت","الأحد") -> الجمعة | F20: =IF(SUM(C20:E20)=0,0,SUM(C20:E20)) -> 0
A21: 46221 | B21: =CHOOSE(WEEKDAY(A21,2),"الاثنين","الثلاثاء","الأربعاء","الخميس","الجمعة","السبت","الأحد") -> السبت | F21: =IF(SUM(C21:E21)=0,0,SUM(C21:E21)) -> 0
A22: 46222 | B22: =CHOOSE(WEEKDAY(A22,2),"الاثنين","الثلاثاء","الأربعاء","الخميس","الجمعة","السبت","الأحد") -> الأحد | F22: =IF(SUM(C22:E22)=0,0,SUM(C22:E22)) -> 0
A23: 46223 | B23: =CHOOSE(WEEKDAY(A23,2),"الاثنين","الثلاثاء","الأربعاء","الخميس","الجمعة","السبت","الأحد") -> الاثنين | F23: =IF(SUM(C23:E23)=0,0,SUM(C23:E23)) -> 0
A24: 46224 | B24: =CHOOSE(WEEKDAY(A24,2),"الاثنين","الثلاثاء","الأربعاء","الخميس","الجمعة","السبت","الأحد") -> الثلاثاء | F24: =IF(SUM(C24:E24)=0,0,SUM(C24:E24)) -> 0
A25: 46225 | B25: =CHOOSE(WEEKDAY(A25,2),"الاثنين","الثلاثاء","الأربعاء","الخميس","الجمعة","السبت","الأحد") -> الأربعاء | F25: =IF(SUM(C25:E25)=0,0,SUM(C25:E25)) -> 0
A26: 46226 | B26: =CHOOSE(WEEKDAY(A26,2),"الاثنين","الثلاثاء","الأربعاء","الخميس","الجمعة","السبت","الأحد") -> الخميس | F26: =IF(SUM(C26:E26)=0,0,SUM(C26:E26)) -> 0
A27: 46227 | B27: =CHOOSE(WEEKDAY(A27,2),"الاثنين","الثلاثاء","الأربعاء","الخميس","الجمعة","السبت","الأحد") -> الجمعة | F27: =IF(SUM(C27:E27)=0,0,SUM(C27:E27)) -> 0
A28: 46228 | B28: =CHOOSE(WEEKDAY(A28,2),"الاثنين","الثلاثاء","الأربعاء","الخميس","الجمعة","السبت","الأحد") -> السبت | F28: =IF(SUM(C28:E28)=0,0,SUM(C28:E28)) -> 0
A29: 46229 | B29: =CHOOSE(WEEKDAY(A29,2),"الاثنين","الثلاثاء","الأربعاء","الخميس","الجمعة","السبت","الأحد") -> الأحد | F29: =IF(SUM(C29:E29)=0,0,SUM(C29:E29)) -> 0
A30: 46230 | B30: =CHOOSE(WEEKDAY(A30,2),"الاثنين","الثلاثاء","الأربعاء","الخميس","الجمعة","السبت","الأحد") -> الاثنين | F30: =IF(SUM(C30:E30)=0,0,SUM(C30:E30)) -> 0
... A34: 46234 | B34: =CHOOSE(WEEKDAY(A34,2),"الاثنين","الثلاثاء","الأربعاء","الخميس","الجمعة","السبت","الأحد") -> الجمعة | F34: =IF(SUM(C34:E34)=0,0,SUM(C34:E34)) -> 0
A35: الإجمالي | C35: =SUM(C4:C34) -> 67926 | D35: =SUM(D4:D34) -> 8120 | E35: =SUM(E4:E34) -> 7005 | F35: =SUM(F4:F34) -> 83051

Sheet تفصيلة اليوم
AJ1: من 8 الي 12 | AM1: 46214 | AT1: =SUM(AU4+AU6+AU9) -> 7225
A2: 46204 | AA2: 46211 | AE2: 46212 | AI2: 46213 | AQ2: 46215 | AU2: 46216 | AY2: 46217 | BC2: 46218 | BG2: 46219 | BK2: 46190 | BO2: 46221
F3: 46206 | I3: 46207 | M3: 46208 | Q3: 46209 | W3: 46210 | AM3: 150 | AN3: دليفري | AO3: مصروفات نثرية
A4: 2200 | B4: تحويل لمستر عبدالله | AA4: 1000 | AB4: مياه | AC4: 10 كراتين | AE4: 80 | AF4: دليفري العماوي | AI4: 550 | AJ4: الهنا | AM4: 630 | AN4: فاكهه | AO4: مشتريات | AQ4: 970 | AR4: الهنا | AS4: 70 دليفري | AU4: 5105 | AV4: العماوي | AW4: فاتورة | AY4: 3000 | AZ4: م عبد الله | BA4: قبض شهر 6 | BC4: 585 | BD4: مستر جمعة | BE4: تحويل | BG4: =110+60 -> 170 | BH4: م جمعة | BI4: تحويل | BK4: =165+280 -> 445 | BL4: م جمعة | BM4: تحويل | BO4: 250 | BP4: م جمعة | BQ4: تحويل
A5: 1530 | B5: الهنا | F5: 1360 | G5: فواكه الهنا | I5: 950 | J5: تورته | M5: 10 | N5: عبد الله محمد | Q5: 2940 | R5: الهنا | T5: خصم | W5: 350 | X5: ترته | AA5: 30 | AB5: دليفري | AE5: 985 | AF5: تحويل الي مستر جمعة | AI5: 80 | AJ5: دليفري الهنا | AM5: 2750 | AN5: تصفية لحد شهر 6 | AO5: محمد اشرف | AQ5: 70 | AR5: م جمعة | AS5: تحويل | AU5: 1660 | AV5: تصفيات محمد اشرف و خالص | AY5: 50 | AZ5: بدل مواصلات عبد الله و ادم | BC5: 1020 | BD5: م عبد الله | BE5: تحويل | BG5: 345 | BH5: م عبد الله | BI5: تحوبل | BK5: =133+80 -> 213 | BL5: م عبد الله | BM5: تحويل | BO5: =145+90+80+200+420+110+350+30+230+120 -> 1775 | BP5: م عبد الله | BQ5: تحويل
A6: 1530 | B6: كهرباء | F6: 220 | G6: تحويل فودافون كاش الي عبد الله | I6: 1570 | J6: طلبات | M6: 1000 | N6: محمد صبحي بهنسي | Q6: 175 | R6: بريل | T6: محمد رافت ربع يوم | W6: 230 | X6: موز دليفري العماوي | AA6: 205 | AB6: الهنا | AE6: 270 | AF6: طليات | AI6: 40 | AJ6: تحويل الي م عبد الله | AM6: 6935 | AN6: العماوي | AO6: مشتريات | AQ6: 100 | AR6: م جمعة | AS6: تحويل | AU6: 1290 | AV6: الهنا | AW6: دلفري 40 | AY6: 100 | AZ6: بدل مواصلات احمد هشش و اسلام و محمود | BC6: 30 | BD6: رضا | BG6: 1000 | BH6: احمد الجهري | BK6: 100 | BL6: م احمد | BM6: تحويل | BO6: 5055 | BP6: مشتريات | BQ6: العماوي ومنظفات
A7: 150 | B7: دليفري العماوي | F7: 145 | G7: تحويل انستا الي مستر جمعة | I7: 5000 | J7: العماوي | M7: =150+75+10+195 -> 430 | N7: تحويل لي مستر عبد الله | Q7: 400 | R7: تشيزكيك | T7: خصم رياض 3 ايام غياب بدون اذن | W7: 11000 | X7: فراشة (شاشة+كراشي) | AA7: 4400 | AB7: فاتورة مياه | AC7: 50 كارتونة مياه | AE7: 1115 | AF7: فاكهة الهنا | AI7: 335 | AJ7: تحويل الي م عبد الله | AM7: =360+20 -> 380 | AN7: تحويل الي مستر عبد الله | AO7: تحويل | AQ7: 35 | AR7: م جمعة | AS7: تحويل | AU7: 650 | AV7: م عبد الله | AY7: 1950 | AZ7: مستلزمات مطبخ | BC7: 130 | BD7: سيف خمزة | BG7: 200 | BH7: احمد الطيب | BK7: 576 | BL7: م احمد عاشور | BM7: مسحوبات نقديه | BO7: 210 | BP7: ثلج
A8: 80 | B8: دليفري العماوي | F8: 750 | G8: صيانة تلاجة | I8: 1425 | J8: فكهاني الهنا | M8: =130+150 -> 280 | N8: تحويل لي مستر جمعة | Q8: 3000 | R8: سيف عصام تقفيل | S8: تصفية | T8: خصم علي عبد الله 3 ايام غياب بدون اذن | W8: 3370 | X8: ليد مستر جمعة | AA8: 250 | AE8: 70 | AF8: دليفري الهنا | AI8: 15 | AJ8: فارس | AM8: 100 | AN8: انستا باي م جمعة | AO8: تحويل | AQ8: 135 | AR8: م عبد الله | AS8: تحويل | AU8: 500 | AV8: بنزين و زيت للمكينة | AY8: 750 | AZ8: تورته | BC8: 3020 | BD8: عبد الله | BE8: ? | BG8: 500 | BH8: اسلام رمضان | BK8: 48 | BL8: م جمعة | BM8: مسحوبات نقديه | BO8: 3000 | BP8: محمود | BQ8: قبص ولا سلفه ؟
A9: 150 | B9: مياه توصيلة | F9: 18000 | G9: 8فراشة و 10تسديد لي العماوي | I9: 180 | J9: تحويل فودافون الي مستر عبد الله | M9: 1330 | N9: قبض احمد هشش | O9: خالص | Q9: 150 | R9: دليفري العماوي | W9: 1500 | X9: درون | AA9: 4470 | AB9: تصفية عبد الله و رياض | AE9: 300 | AF9: تحويل الي مستر عبد الله | AI9: 10 | AJ9: محمد صبري | AM9: 50 | AN9: انستا باي جمعة | AO9: تحويل | AQ9: 265 | AR9: م عبد الله | AS9: تحويل | AU9: 830 | AV9: سكر + علب تاك اواي | AY9: 535 | AZ9: فاكهه | BC9: 52 | BD9: احمد الجهري | BG9: 15 | BH9: محمود البهنسي | BK9: 392 | BL9: ابو عمار | BM9: مسحوبات نقديه | BO9: 400 | BP9: سيف حمزة
A10: 7627 | B10: كاش | F10: 570 | G10: تلج | I10: 125 | J10: تحويل انستا الي مستر جمهة | M10: 1290 | N10: قبض محمد عزت | O10: تصفية | Q10: 9000 | R10: من الدرج لمستر جمعة | W10: 465 | X10: تلج | AA10: =120+140+290 -> 550 | AB10: تحوبل ال مستر جمعة انستا | AE10: 30 | AF10: محمد صيري | AI10: 50 | AJ10: محمد صبري | AM10: 50 | AN10: كاش م عبدالله | AO10: تحويل | AQ10: 60 | AR10: محمد صبري | AS10: سلفة | AU10: 30 | AV10: مستر جمعة | AW10: =SUM(AU10:AU12) -> 300 | AY10: 465 | AZ10: ثلج | BA10: 150 دليفري | BC10: 67.5 | BD10: محمود عثمان | BG10: 1000 | BH10: ادم ياسر | BK10: 80 | BL10: م عبد الله | BO10: 1000 | BP10: محمد صبحي
A11: 100 | B11: مكافئة فهمي | E11: منهم 3000 من الخزنة | F11: 5000 | G11: نت | I11: 915 | J11: تحوبل فودافون الي مستر عبد الله | M11: 2000 | N11: عبد الله محمد عبد المنعم | O11: تصفية | Q11: 600 | R11: سلفة ادم برستا | W11: =415+60+120+110 -> 705 | X11: تحوبل لمستر جمعة | AA11: 50 | AB11: تحويل الي م عبد الله | AE11: 30 | AF11: فارس | AI11: 20 | AJ11: احمد الجهري | AM11: 150 | AN11: كاش م عبدالله | AO11: تحويل | AQ11: 100 | AR11: احمد هشش | AS11: بدل موصلات | AU11: 65 | AV11: مستر جمعة | AY11: 36 | AZ11: فهمي | BC11: 67.5 | BD11: يوسف شحته | BG11: 261 | BH11: عمار | BK11: 1000 | BL11: عمار البهنسي | BM11: قبض ولا سلفة | BO11: 150 | BP11: احمد الطيب
A12: 100 | B12: مكافئة عمار | F12: 30 | G12: محمد رافت | I12: 395 | J12: تحويل فودافون الي مستر عبد الله | M12: 2350 | N12: بسكوت | Q12: 100 | R12: محمد رافت سلفة | W12: =60+335+80 -> 475 | X12: تحويل لمستر عبد الله | AA12: 50 | AB12: احمد الجهري | AE12: 30 | AF12: عبد الرحمن | AI12: 10000 | AJ12: العماوي | AK12: سداد | AM12: 200 | AN12: احمد الجهري | AO12: سلفة | AR12: اسلام | AS12: بدل موصلات | AU12: 205 | AV12: مستر جمعة | AY12: 100 | AZ12: سيف | BC12: 120 | BD12: فارس | BG12: 100 | BH12: احمد الطيب | BK12: 500 | BL12: فهمي | BO12: 500 | BP12: محمد صلاح
A13: 1110 | B13: سلف | F13: 200 | G13: محمد صلاح | I13: 150 | J13: فهمي | M13: 100 | N13: بدل موصلات هشش | Q13: =65+190+175+195 -> 625 | R13: تحويل الي مستر جمعة | W13: 1500 | X13: كاميرا فوتوجرافر | AA13: 115 | AB13: فارس | AE13: 7400 | AF13: العماوي | AJ13: كاش | AM13: 60 | AN13: فارس | AO13: سلفة | AR13: محمود | AS13: بدل موصلات | AU13: 315 | AV13: مستر عبد الله | AW13: =SUM(AU13:AU19) -> 955 | AY13: 500 | AZ13: احمد هشش | BC13: 30 | BD13: محمود محروص | BG13: 20 | BH13: محمد صبري | BK13: 200 | BL13: سيف حمزه | BO13: 10 | BP13: فارس
A14: 3000 | B14: ادم | C14: قبض
A15: 1220 | B15: اجل مستر طارق | F15: 100 | G15: بدل موصلات احمد هشش | I15: 125 | J15: مستر عبد الله | M15: 2750 | N15: سيف فخري تقفيل شهر 6 | O15: تصفية | Q15: 100 | R15: فهمي | W15: 3000 | X15: فارس | Y15: قيض | AA15: 1000 | AB15: ادم من مرتب شهر 6 و باقي ليه 3 | AE15: 50 | AF15: محمد صبري | AI15: 11100 | AJ15: الاجمالي | AM15: 100 | AN15: احمد هشش | AO15: سلفة | AQ15: 25 | AR15: احمد الجهري | AS15: سلفة | AU15: 180 | AV15: مستر عبد الله | AY15: 10 | AZ15: م عبد الله | BC15: 500 | BD15: ادم | BG15: 10 | BH15: فارس | BK15: 10 | BL15: اسلام رمضان | BO15: 10 | BP15: م عبد الله
A16: =SUM(A4:A15) -> 18797 | B16: الاجمالي | F16: 200 | G16: فهمي | I16: 200 | J16: ادم | M16: 3000 | N16: مرتب ادم بارستا | O16: كان واخد 2000 كمان من مستر جمعة | Q16: 10 | R16: محمد صيري | S16: مياه | W16: 100 | X16: سلفة محمد صبري | AA16: 100 | AB16: احمد هشش | AE16: 500 | AF16: اسلام رمضان | AI16: 11290 | AJ16: الفاتورة علي الجهاز | AM16: 150 | AN16: اسلام رمضان | AO16: سلفة | AQ16: 50 | AR16: ادم | AS16: بدل موصلات | AU16: 115 | AV16: مستر عبد الله | AY16: 10 | AZ16: هشش | BC16: 100 | BD16: محمود رمضان | BG16: 72 | BH16: فارس | BK16: 20 | BL16: محمد صبري | BO16: 60 | BP16: فارس
A17: 18717 | B17: الفاتورة علي الجهاز | F17: =50+30 -> 80 | G17: عبد الله محمد | I17: 350 | J17: محمد عزت | M17: 515 | N17: طلبات | Q17: 30 | R17: فارس | S17: قهوة | W17: 100 | X17: احمد هشش | AA17: 50 | AB17: محمد صبري | AE17: 1000 | AF17: ادم برستا | AM17: 150 | AN17: محمد رمضان | AO17: سلفة | AR17: عبد الله | AS17: بدل موصلات | AU17: 80 | AV17: مستر عبد الله | AY17: 10 | AZ17: محمودرمضان | BC17: 100 | BD17: احمد الطيب | BG17: 72 | BH17: محمد صبري | BK17: 10 | BL17: احمد الجهري | BO17: 60 | BP17: محمد صبري
A18: =18797-18717 -> 80 | B18: الزيادة | F18: 10 | G18: مستر عبدالله | I18: 300 | J18: محمد صبحي | Q18: 10 | R18: عمار | W18: 6493 | X18: صافي كاش | AA18: 15 | AB18: فهمي | AE18: 100 | AF18: احمد هشش | AM18: 25 | AN18: احمد الطيب | AO18: سلفة | AQ18: 10 | AR18: فهمي | AS18: سلفة | AU18: 50 | AV18: مستر عبد الله | AY18: 10 | AZ18: فارس | BC18: 30 | BD18: احمد الجهري | BG18: 30 | BH18: محمد صبري | BK18: 50 | BL18: فارس هاني | BO18: 60 | BP18: احمد الجهري
F19: 10 | G19: محمود | I19: 100 | J19: سيف عصام | M19: 2000 | N19: محمد صبري | O19: مرتب | Q19: 100 | R19: بدل مواصلات احمد هشش | W19: =SUM(W5:W18) -> 29288 | X19: الاجمالي | AB19: محمد صبري | AC19: خصم نص يوم | AE19: 500 | AF19: محمد صبحي | AM19: 15 | AN19: بسكوت | AQ19: 200 | AR19: احمد الطيب | AS19: سلفة | AU19: 215 | AV19: مستر عبد الله | AY19: 50 | AZ19: الطيب | BC19: 50 | BD19: محمد صبري | BG19: 100 | BH19: احمد هشش | BK19: 500 | BL19: محمد صبري | BO19: 60 | BP19: احمد الطيب
F20: 10 | G20: محمد عزت | I20: 125 | J20: محمد صبري | M20: 1275 | N20: تم تسليم كاش | Q20: 10 | R20: اسلام رمضان | S20: بسكوت | W20: 29288.75 | X20: الفاتورة علي الجهاز | AB20: فارس | AC20: خصم نصف يوم | AE20: 2000 | AF20: مكسرات | AM20: 50 | AN20: احمد الطيب | AO20: سلفة | AQ20: 500 | AR20: محمد صبحي | AS20: سلفة | AU20: 300 | AV20: احمد الطيب | AY20: 360 | AZ20: م جمعة | BC20: 50 | BD20: محمد صبري | BG20: 50 | BH20: عبد الله | BI20: بدل مواصلات | BK20: 100 | BL20: احمد هشش | BO20: 3183 | BP20: كاش
F21: 30 | G21: محمد صبري | I21: 125 | J21: عبد الله | M21: =SUM(M5:M20) -> 18330 | N21: الاجمالي | Q21: 195 | R21: عبد الله محمد عبد المنعم | S21: موز حليب | AB21: عبد الرحمن | AC21: خصم نص يوم | AE21: =145+125+120 -> 390 | AF21: تحويل الي مستر عبد الله | AJ21: =335+40 -> 375 | AM21: 100 | AN21: فارس | AO21: سلفة | AQ21: 500 | AR21: تحت حساب اصلاح | AU21: 200 | AV21: رضا | AY21: 432 | AZ21: م هشام | BC21: 200 | BD21: نورهان | BG21: 60 | BH21: زبادي | BK21: 50 | BL21: عبد الله و ادم | BM21: بدل مواصلات | BO21: 100 | BP21: احمد هشش
F22: 200 | G22: عيد نوح | I22: 125 | J22: فارس | M22: 18342 | N22: الفاتورة علي الجهاز | Q22: 2200 | R22: تم تسليم كاش | AA22: =3753-500 -> 3253 | AB22: واصل كاش | AF22: خصم نصف يوم | AG22: ادم | AM22: 4650 | AN22: تم تسليم كاش | AQ22: 15 | AR22: عمار | AS22: سلفة | AU22: 500 | AV22: فهمي | AY22: 504 | AZ22: ابو عمار | BC22: 1000 | BD22: محمد صلاح | BG22: 1460 | BH22: الهنا | BI22: 50 دليفري | BK22: 3100 | BL22: مكسرات | BO22: 50 | BP22: ادم و عبد الله | BQ22: بدل مواصلات
F23: =SUM(F5:F22) -> 26915 | G23: الاجمالي | I23: 100 | J23: هشش | M23: 12 | N23: عجز | Q23: =SUM(Q5:Q22) -> 19645 | R23: الاجمالي | AA23: =SUM(AA4:AA22) -> 15538 | AB23: الاجمالي | AF23: خصم تص يوم | AG23: فهمي | AI23: =300+390 -> 690 | AM23: =SUM(AM3:AM22) -> 16695 | AN23: الاجمالي | AQ23: 80 | AR23: نورهان | AS23: بدل موصلات | AU23: 500 | AV23: ادم من حساب شهر 6 و خالص | AY23: =150+630 -> 780 | AZ23: م عبد الله | BA23: تحويل | BC23: 60 | BD23: احمد الجري | BG23: 200 | BH23: دليفري | BK23: 210 | BL23: الهنا | BM23: 30 دليفري | BO23: =SUM(BO4:BO22) -> 15933 | BP23: الاجمالي
F24: 26073 | G24: الفاتورة علي الجهاز | I24: 25 | J24: فارس | Q24: 19450 | R24: الفاتورةعلي الجهاز | AA24: 15538 | AB24: الفاورة علي الجهاز | AE24: 70 | AF24: دليفري العماوي | AM24: 16695 | AN24: الفاتورة علي الجهاز | AQ24: 1500 | AR24: ادم ياسر | AS24: من قبض شهر 6 | AU24: 1000 | AV24: احمد هشش | AY24: 7164 | AZ24: كاش | BC24: 30 | BD24: مسامير | BG24: 450 | BH24: عبد الرحمن | BI24: تصفية | BK24: 6832 | BL24: سداد الي م احمد نظير سداد فاتورة العماوي | BO24: 15933 | BP24: الفاتورة ع الجهاز
F25: 842 | G25: يوجد زيادة | I25: 25 | J25: محمد عزت | Q25: =Q23-Q24 -> 195 | R25: يوجد زيادة | AE25: 1540 | AF25: تم تسليم | AQ25: 7000 | AR25: العماوي | AS25: مشتريات | AU25: 50 | AV25: عبد الله | AY25: =175+40+55 -> 270 | AZ25: م جمعة | BA25: تحويل | BC25: 50 | BD25: ادم | BE25: بدل مواصلات | BG25: 3310 | BH25: مشتريات م جمعة | BK25: =SUM(BK4:BK24) -> 14436 | BL25: الاجمالي | BP25: خصم يومين احمد الطيب
F26: 1500 | G26: يوجد كمان درون | I26: 800 | J26: محمد صلاح | AE26: =SUM(AE4:AE25) -> 16460 | AF26: الاجمالي | AQ26: 1428 | AR26: محمد صبحي | AS26: سلفة | AU26: 100 | AV26: احمد هشش | AY26: =SUM(AY4:AY25) -> 17086 | AZ26: الاجمالي | BC26: 100 | BD26: احمد هشش | BE26: بدل مواصلات | BG26: 4120 | BH26: كاش | BK26: 14436 | BL26: الفاتوؤة ع الجهاز | BP26: خيم يوم محمد صبري
I27: 150 | J27: دليفري | AE27: 16422 | AF27: الفاتورة علي الجهاو | AN27: =AM7+AM10+AM11 -> 580 | AQ27: 4201 | AR27: كاش | AS27: نقدي | AU27: 85 | AV27: محمد صبحي | AY27: 17086 | AZ27: الفاتورة علي الجهاز | BC27: 100 | BD27: سيف خمزة | BE27: مكافاة | BG27: =SUM(BG4:BG26) -> 13545 | BH27: الاجمالي | BL27: خصم نصف يوم سيف فخري
I28: 1955 | J28: تم تسليم كاش | AE28: =AE26-AE27 -> 38 | AF28: يوجد زيادة | AQ28: =SUM(AQ4:AQ27) -> 17244 | AR28: الاجمالي | AU28: 10 | AV28: م عبد الله | BC28: 1282 | BD28: الهنا | BE28: 50 دليفري | BG28: 13543 | BH28: الفاتورة ع الجهاز | BL28: خصم نصف يوم احممد الجهري | BQ28: =SUM(BO8:BO19) -> 5310
I29: =SUM(I5:I28) -> 15215 | J29: الاجمالي | R29: 3000 | AQ29: 17244 | AR29: الفاتورة ع الجهاز | AU29: 75 | AV29: فارس | BC29: 200 | BD29: دليفري | BG29: في خصومات | BL29: خصم ربع يوم محمد صبري
I30: 14969 | J30: الفاتورة علي الجهاز | AU30: 75 | AV30: احمد جوهري | BC30: 6180 | BD30: العماوي | BE30: فاتورة | BG30: تم سداد لي العماوي 7800 من جيب م احمد كمال الخاص
I31: =15215-14969 -> 246 | J31: يوجد زيادة | AR31: =135+265 -> 400 | AU31: 3000 | AV31: عمار محمد | AW31: قبض شهر 6 | BC31: =785+70 -> 855 | BD31: العماوي | BE31: 70 دليفري | BM31: =SUM(BK9:BK21) -> 2912
AU32: 80 | AV32: بدل مواصلات رضا ونور | BC32: 4255 | BD32: كاش
AU33: 15 | AV33: محمود بهنسي | BC33: =SUM(BC4:BC32) -> 20264 | BD33: اجمالي
C34: 46222 | AU34: 60 | AV34: اسلام | BC34: 20192 | BD34: الفاتورة ع الجهاز
AU35: 60 | AV35: محمود رمضان | BC35: في خصومات
C36: ملاحظات | D36: المبلغ | E36: البيان | AU36: 360 | AV36: سيف فخري
D37: 150 | E37: دليفري ثلج | AU37: 5405 | AV37: كاش | AY37: =3470-500 -> 2970 | BD37: =BC34-BC33 -> -72
D38: 90 | E38: منديل | AU38: =SUM(AU4:AU37) -> 23165 | AV38: الاجمالي
D39: 200 | E39: دليفري العماوي | AU39: 23165.75 | AV39: الفاتورة علي الجهاز
D40: =50+70+150+65+255 -> 590 | E40: تحويلات م جمعة
...

Sheet فواتير
C2: سجل متابعة فواتير المورد (العماوي)
C5: التاريخ | E5: بيان الحركة | I5: مصدر الدفع
C6: 46205 | E6: تم سداد 10000 جنيه من فاتورة العماوي | I6: الايراد اليومي
C7: 46206 | E7: تم سداد 10000 جنيه من فاتورة العماوي | I7: الايراد اليومي
C8: 46207 | E8: تم سداد 5000 جنيه من فاتورة العماوي | I8: الايراد اليومي
E9: يوجد فاتورة ناقصة بقيمة 630 حنيه | K9: =79290+630 -> 79920 | L9: قيمة مشتريات العماوي
C10: 46213 | E10: تم سداد 10000 جنيه من فاتورة العماوي | I10: الايراد اليومي | K10: =79290+630 -> 79920 | L10: فواتير شهر 7
C11: 46214 | E11: تم سداد 33000 من فاتورة العماوي | I11: الخزنة | K11: 74935 | L11: سداد
C12: 46214 | E12: تم سداد 6935 من فاتورة العماوي | I12: الايراد اليومي
C13: 46215 | E13: تم سداد 7000 | I13: الايراد اليومي
L14: =10000+10000+5000+10000+33000+6935 -> 74935
G29: 46204
C30: تم سداد 10000
A31: #VALUE! | I31: #VALUE! | P31: #VALUE!
A58: #VALUE!
B92: 46206
N93: 46207
Y94: 46209
B95: #VALUE! | N95: #VALUE!
X96: #VALUE! | AG96: في فاتورة ناقصة بقيمة 630
T113: تم سداد 5000
T114: باقي 24187
I120: سداد 10000
I121: باقي من فاتورة العماوي 15297
E127: 46212
A129: #VALUE!
F130: #VALUE! | K130: #VALUE! | O130: #VALUE!
S136: تم سداد 10000 من الايراد
S140: تم سداد 33000 من الخزنة
A154: 46214
A156: #VALUE!
F157: تم سداد هذه الفاتورة انستا باي وخصكها من الايراد اليومي
F160: #VALUE!
F182: =79290+630 -> 79920
A184: 46215
A186: #VALUE!

Sheet ملخص شهري
A1: الملخص الشهري
A3: Column1 | B3: Column2 | C3: Column3 | D3: Column4 | E3: Column5 | F3: Column6 | G3: Column7
A4: الشهر | B4: إجمالي الإيرادات | C4: إجمالي المشتريات | D4: إجمالي المصروفات النثرية | E4: إجمالي الرواتب | F4: صافي الربح/الخسارة | G4: ملاحظات
A5: 7 | B5: =SUM('تقفيلة اليوم'!N37) -> 353493.74 | C5: =SUM('المشتريات اليومية'!L29) -> 178985.94 | D5: =SUM('المصروفات النثرية'!C5:C269) -> 37480 | E5: _ | F5: 49115

Sheet test
Y2: شهر 6 و 7
L3: م عبدالله | Y3: م عبدالله
L4: التاريخ | M4: تحويلات | N4: سلف | S4: واصل لي م عبدالله لحد 30/6 | Y4: التاريخ | Z4: تحويلات | AA4: سلف
S5: =300+810+20+500+230+380+195+225+505+560 -> 3725 | Y5: 46189 | AA5: 300
L6: 46189 | N6: 300 | Y6: 46190
L7: 46190 | Y7: 46191 | Z7: 810
L8: 46191 | M8: =370+275+140 -> 785 | O8: =570+240 -> 810 | Y8: 46192 | Z8: 20
L9: 46192 | O9: 20 | Y9: 46193 | Z9: 500
L10: 46193 | M10: 370 | O10: =440+60 -> 500 | Y10: 46194 | AI10: الحساب حتى تاريخ : 14/07/2026 | AS10: التاريخ من 1/7 : الي 13/7
L11: 46194 | Y11: 46195
L12: 46195 | Y12: 46196 | Z12: 230 | AI12: عبد الله | AJ12: اسم الموظف | AS12: اجمالي الارادات | AT12: اجمالي المشتريات | AU12: اجمالي المصروفات النثرية
L13: 46196 | M13: 230 | R13: م عبد الله | Y13: 46197 | Z13: 380 | AI13: =SUM(Z5:Z34) -> 12095 | AJ13: إجمالي التحويلات | AS13: =SUM('تقفيلة اليوم'!N6:N18) -> 248671.74 | AT13: =SUM('المشتريات اليومية'!G5:G46) -> 147888.44 | AU13: =SUM('المصروفات النثرية'!C5:C39) -> 36230 | AV13: {=AT13:AU13} -> 147888.44 | AW13: 36230
L14: 46197 | M14: =130+345+140+205 -> 820 | O14: =100+95+185 -> 380 | Q14: بيع كرتون | R14: تحويلات | S14: سلف | T14: الاجمالي | Y14: 46198 | Z14: =160+35 -> 195 | AI14: =SUM(AA5:AA34) -> 685 | AJ14: إجمالي السلف | AT14: اجمالي المصروفات : 184118.44
L15: 46198 | M15: =160+35 -> 195 | Q15: 560 | R15: 8375 | S15: =300+100+10+10+125 -> 545 | T15: =SUM(Q15:S15) -> 9480 | U15: فرق | Y15: 46199 | AI15: =SUM(Z35) -> 560 | AJ15: بيع الكرتون
L16: 46199 | V16: 375 | Y16: 46200 | Z16: 225 | AI16: =SUM(Z36) -> 3000 | AJ16: المقبوض من شهر 6 | AU16: =SUM(AT13:AU13) -> 184118.44
L17: 46200 | M17: =260+100+65 -> 425 | O17: =160+65 -> 225 | Y17: 46201 | AA17: 20 | AI17: =SUM(AI13:AI16) -> 16340 | AJ17: الاجمالي الكلي
L18: 46201 | N18: 20 | Q18: بيع كرتون | R18: تحولات | S18: سلف | T18: اجمالي | Y18: 46202
L19: 46202 | Q19: 560 | R19: =SUM(M5:M29) -> 8630 | S19: 665 | T19: =SUM(Q19:S19) -> 9855 | Y19: 46203 | Z19: =330+175 -> 505 | AA19: 100 | AS19: التاريخ من 7/6 : الي 13/7
L20: 46203 | M20: =330+175 -> 505 | N20: 100 | Y20: 46204 | Z20: 2200 | AA20: 100
L21: 46204 | M21: 2200 | N21: 100 | Y21: 46205 | Z21: =60+175+100+100 -> 435 | AA21: 10 | AS21: =246428+248671.74 -> 495099.74 | AT21: اجمالي الارادات
L22: 46205 | M22: =60+175+100+100 -> 435 | N22: 10 | Y22: 46206 | Z22: 220 | AA22: 10 | AS22: 311498.44 | AT22: اجمالي المشتريات
L23: 46206 | M23: 220 | N23: 10 | Y23: 46207 | Z23: =395+915+180 -> 1490 | AA23: 125 | AS23: 65315 | AT23: اجمالي المصروفات النثرية
AS24: 85914 | AT24: اجمالي المرتبات
L25: 46207 | M25: =395+915+180 -> 1490 | N25: 125 | Y25: 46208 | Z25: =10+195+75+150 -> 430 | AS25: =SUM(AS22:AS24) -> 462727.44 | AT25: اجمالي المصروفات
L26: 46208 | M26: =10+195+75+150 -> 430 | Y26: 46209 | Z26: 100
L27: 46209 | O27: =150+10 -> 160 | Y27: 46210 | Z27: 475
L28: 46210 | M28: 475 | Y28: 46211 | Z28: 100 | AS28: التاريخ من 7/6 : الي 13/7
L29: 46211 | M29: 50 | O29: 100 | Y29: 46212 | Z29: 690 | AS29: اجمالي الارادات | AT29: اجمالي المصروفات | AU29: صافي الربح/الخسارة
Y30: 46213 | Z30: 375 | AS30: =246428+248671.74 -> 495099.74 | AT30: 462727.44 | AU30: =SUM(AS30-AT30) -> 32372.3
Y31: 46214 | Z31: 580
Y32: 46215 | Z32: 400
Y33: 46216 | Z33: 955 | AA33: 10
Y34: 46217 | Z34: 780 | AA34: 10 | AS34: التاريخ من 1/7 : الي 13/7
Z35: 560 | AA35: بيع كرتون | AS35: اجمالي الارادات | AT35: اجمالي المصروفات | AU35: صافي الربح/الخسارة
Z36: 3000 | AA36: قبض | AS36: =SUM('تقفيلة اليوم'!N29:N41) -> 353493.74 | AT36: =SUM(AT13:AU13) -> 184118.44 | AU36: =SUM(AS36-AT36) -> 169375.3
M37: 560 | N37: بيع كرتون | Z37: =SUM(AA5:AA34) -> 685 | AA37: اجمالي السلف
M38: =SUM(N6:N29) -> 665 | N38: اجمالي السلف | Z38: =SUM(Z5:Z34) -> 12095 | AA38: اجمالي التحويلات
M39: =SUM(M5:M37) -> 9190 | N39: اجمالي التحويلات | Z39: =SUM(Z35:Z38) -> 16340 | AA39: الاجمالي
M40: 9855 | N40: الاجمالي
AS45: من 1/7 الي : 13/7
...

Sheet الرواتب
A1: جدول الرواتب
C3: الشهر | D3: July 2026
A5: م | B5: اسم الموظف | C5: الوظيفة | D5: الراتب الأساسي | E5: إضافي | F5: قيمة السلفة | G5: خصومات | H5: صافي الراتب | I5: التوقيع
A6: 1 | B6: محمود محمد صبحي | C6: =IF(B6="","",IFERROR(IF(VLOOKUP(B6,الموظفين!$C:$E,2,FALSE())=0,"",VLOOKUP(B6,الموظفين!$C:$E,2,FALSE())),"")) -> هاوس
A7: 2 | B7: محمد احمد صلاح احمد | C7: =IF(B7="","",IFERROR(IF(VLOOKUP(B7,الموظفين!$C:$E,2,FALSE())=0,"",VLOOKUP(B7,الموظفين!$C:$E,2,FALSE())),"")) -> بارستا
A8: 3 | B8: يوسف محمد شحته | C8: =IF(B8="","",IFERROR(IF(VLOOKUP(B8,الموظفين!$C:$E,2,FALSE())=0,"",VLOOKUP(B8,الموظفين!$C:$E,2,FALSE())),"")) -> كابتن
A9: 4 | B9: محمود عثمان فؤاد | C9: =IF(B9="","",IFERROR(IF(VLOOKUP(B9,الموظفين!$C:$E,2,FALSE())=0,"",VLOOKUP(B9,الموظفين!$C:$E,2,FALSE())),"")) -> كابتن
A10: 5 | B10: عبد الله محمد عبد المنعم | C10: =IF(B10="","",IFERROR(IF(VLOOKUP(B10,الموظفين!$C:$E,2,FALSE())=0,"",VLOOKUP(B10,الموظفين!$C:$E,2,FALSE())),""))
A11: 6 | B11: سيف فخري فوزي | C11: =IF(B11="","",IFERROR(IF(VLOOKUP(B11,الموظفين!$C:$E,2,FALSE())=0,"",VLOOKUP(B11,الموظفين!$C:$E,2,FALSE())),"")) -> هاوس
A12: 7 | B12: فارس احمد مصطفي | C12: =IF(B12="","",IFERROR(IF(VLOOKUP(B12,الموظفين!$C:$E,2,FALSE())=0,"",VLOOKUP(B12,الموظفين!$C:$E,2,FALSE())),""))
A13: 8 | B13: محمد صبري محمد | C13: =IF(B13="","",IFERROR(IF(VLOOKUP(B13,الموظفين!$C:$E,2,FALSE())=0,"",VLOOKUP(B13,الموظفين!$C:$E,2,FALSE())),"")) -> ويتر
A14: 9 | B14: عمار محمد صبحي عبد الفتاح | C14: =IF(B14="","",IFERROR(IF(VLOOKUP(B14,الموظفين!$C:$E,2,FALSE())=0,"",VLOOKUP(B14,الموظفين!$C:$E,2,FALSE())),"")) -> كاشير
A15: 10 | B15: رياض حامد رياض عطية | C15: =IF(B15="","",IFERROR(IF(VLOOKUP(B15,الموظفين!$C:$E,2,FALSE())=0,"",VLOOKUP(B15,الموظفين!$C:$E,2,FALSE())),""))
A16: 11 | B16: سيف عصام طايل | C16: =IF(B16="","",IFERROR(IF(VLOOKUP(B16,الموظفين!$C:$E,2,FALSE())=0,"",VLOOKUP(B16,الموظفين!$C:$E,2,FALSE())),""))
A17: 12 | B17: منة الله سيف محمد راغب | C17: =IF(B17="","",IFERROR(IF(VLOOKUP(B17,الموظفين!$C:$E,2,FALSE())=0,"",VLOOKUP(B17,الموظفين!$C:$E,2,FALSE())),""))
... A23: 18 | B23: احمد هش هش | C23: =IF(B23="","",IFERROR(IF(VLOOKUP(B23,الموظفين!$C:$E,2,FALSE())=0,"",VLOOKUP(B23,الموظفين!$C:$E,2,FALSE())),""))
A24: 19 | B24: محمد صبحي بهنسي
A25: 20 | B25: ابراهيم بدر

Sheet حضور وانصراف
A1: تسجيل الحضور والانصراف
A2: اسم الموظف | E2: السبت | G2: الاحد | I2: الاثنين | K2: الثلاثاء | M2: الاربعاء | O2: الخميس | Q2: الجمعة | S2: ملاحظات
E4: حضور | F4: انصراف | G4: حضور | H4: انصراف | I4: حضور | J4: انصراف | K4: حضور | L4: انصراف | M4: حضور | N4: انصراف | O4: حضور | P4: انصراف | Q4: حضور | R4: انصراف
E7: 0.33333333 | F7: 0.33333333 | G7: 0.33333333 | H7: 0.33333333 | I7: 0.33333333 | J7: 0.33333333 | K7: 0.33333333 | L7: 0.33333333 | M7: 0.33333333 | N7: 0.33333333 | O7: 0.33333333 | P7: 0.33333333 | Q7: 0.33333333 | R7: 0.33333333
E60: =IF(AND(C60<>"",D60<>""),(D60-C60)*24,"")
E61: =IF(AND(C61<>"",D61<>""),(D61-C61)*24,"")
E62: =IF(AND(C62<>"",D62<>""),(D62-C62)*24,"")
E63: =IF(AND(C63<>"",D63<>""),(D63-C63)*24,"")
E64: =IF(AND(C64<>"",D64<>""),(D64-C64)*24,"")
E65: =IF(AND(C65<>"",D65<>""),(D65-C65)*24,"")
E66: =IF(AND(C66<>"",D66<>""),(D66-C66)*24,"")
E67: =IF(AND(C67<>"",D67<>""),(D67-C67)*24,"")
E68: =IF(AND(C68<>"",D68<>""),(D68-C68)*24,"")
E69: =IF(AND(C69<>"",D69<>""),(D69-C69)*24,"")
E70: =IF(AND(C70<>"",D70<>""),(D70-C70)*24,"")
E71: =IF(AND(C71<>"",D71<>""),(D71-C71)*24,"")
... E103: =IF(AND(C103<>"",D103<>""),(D103-C103)*24,"")

Sheet المخزون
A1: المخزون
A2: ملاحظة: يتم تحديث الوارد من شيت المشتريات اليومية، والصادر من شيت الجرد
A4: م | B4: اسم الصنف | C4: سعر الوحدة | D4: رصيد أول المدة | E4: الوارد | F4: الصادر | G4: الرصيد الحالي | H4: قيمة الرصيد
A5: 1 | B5: قهوة | G5: =IF(D5=0,0,D5+E5-F5) -> 0 | H5: =IF(G5=0,0,G5*C5) -> 0
A6: 2 | B6: حليب | G6: =IF(D6=0,0,D6+E6-F6) -> 0 | H6: =IF(G6=0,0,G6*C6) -> 0
A7: 3 | B7: سكر | G7: =IF(D7=0,0,D7+E7-F7) -> 0 | H7: =IF(G7=0,0,G7*C7) -> 0
A8: 4 | B8: شاي | G8: =IF(D8=0,0,D8+E8-F8) -> 0 | H8: =IF(G8=0,0,G8*C8) -> 0
A9: 5 | B9: عصائر | G9: =IF(D9=0,0,D9+E9-F9) -> 0 | H9: =IF(G9=0,0,G9*C9) -> 0
A10: 6 | B10: مياه | G10: =IF(D10=0,0,D10+E10-F10) -> 0 | H10: =IF(G10=0,0,G10*C10) -> 0
A11: 7 | B11: مشروبات غازية | G11: =IF(D11=0,0,D11+E11-F11) -> 0 | H11: =IF(G11=0,0,G11*C11) -> 0
A12: 8 | B12: مستلزمات نظافة | G12: =IF(D12=0,0,D12+E12-F12) -> 0 | H12: =IF(G12=0,0,G12*C12) -> 0
A13: 9 | B13: أكواب ورقية | G13: =IF(D13=0,0,D13+E13-F13) -> 0 | H13: =IF(G13=0,0,G13*C13) -> 0
A14: 10 | B14: بسكويت/حلويات | G14: =IF(D14=0,0,D14+E14-F14) -> 0 | H14: =IF(G14=0,0,G14*C14) -> 0
A15: 11 | B15: زيت طهي | G15: =IF(D15=0,0,D15+E15-F15) -> 0 | H15: =IF(G15=0,0,G15*C15) -> 0
A16: 12 | B16: دقيق | G16: =IF(D16=0,0,D16+E16-F16) -> 0 | H16: =IF(G16=0,0,G16*C16) -> 0
... A19: 15 | B19: مكسرات | G19: =IF(D19=0,0,D19+E19-F19) -> 0 | H19: =IF(G19=0,0,G19*C19) -> 0
A20: الإجمالي | D20: =SUM(D5:D19) -> 0 | E20: =SUM(E5:E19) -> 0 | F20: =SUM(F5:F19) -> 0 | G20: =SUM(G5:G19) -> 0 | H20: =SUM(H5:H19) -> 0

Sheet الجرد
A1: جرد المخزون
A3: التاريخ | B3: الصنف | C3: رصيد النظام | D3: الرصيد الفعلي | E3: الفرق | F3: الحالة | G3: ملاحظات
E4: =IF(C4*D4=0,0,C4-D4) -> 0 | F4: =IF(C4=0,"",IF(E4=0,"مطابق","فيه فرق"))
E5: =IF(C5*D5=0,0,C5-D5) -> 0 | F5: =IF(C5=0,"",IF(E5=0,"مطابق","فيه فرق"))
E6: =IF(C6*D6=0,0,C6-D6) -> 0 | F6: =IF(C6=0,"",IF(E6=0,"مطابق","فيه فرق"))
E7: =IF(C7*D7=0,0,C7-D7) -> 0 | F7: =IF(C7=0,"",IF(E7=0,"مطابق","فيه فرق"))
E8: =IF(C8*D8=0,0,C8-D8) -> 0 | F8: =IF(C8=0,"",IF(E8=0,"مطابق","فيه فرق"))
E9: =IF(C9*D9=0,0,C9-D9) -> 0 | F9: =IF(C9=0,"",IF(E9=0,"مطابق","فيه فرق"))
E10: =IF(C10*D10=0,0,C10-D10) -> 0 | F10: =IF(C10=0,"",IF(E10=0,"مطابق","فيه فرق"))
E11: =IF(C11*D11=0,0,C11-D11) -> 0 | F11: =IF(C11=0,"",IF(E11=0,"مطابق","فيه فرق"))
E12: =IF(C12*D12=0,0,C12-D12) -> 0 | F12: =IF(C12=0,"",IF(E12=0,"مطابق","فيه فرق"))
E13: =IF(C13*D13=0,0,C13-D13) -> 0 | F13: =IF(C13=0,"",IF(E13=0,"مطابق","فيه فرق"))
E14: =IF(C14*D14=0,0,C14-D14) -> 0 | F14: =IF(C14=0,"",IF(E14=0,"مطابق","فيه فرق"))
E15: =IF(C15*D15=0,0,C15-D15) -> 0 | F15: =IF(C15=0,"",IF(E15=0,"مطابق","فيه فرق"))
... E53: =IF(C53*D53=0,0,C53-D53) -> 0 | F53: =IF(C53=0,"",IF(E53=0,"مطابق","فيه فرق"))

Sheet الموردين
A1: بيانات الموردين
A3: م | B3: اسم المورد | C3: رقم الهاتف | D3: العنوان | E3: المنتجات الموردة | F3: اجمالي المبلغ الحالي | G3: مدفوع | H3: المتبقي
A4: 1 | B4: العماوي | F4: 25297 | G4: 10000 | H4: =IF(F4=0,0,F4-G4) -> 15297
F5: =H4+13890 -> 29187 | G5: 5000 | H5: =Table1[[#This Row],[اجمالي المبلغ الحالي]]-5000 -> 24187

Sheet حساب م جمعة و طارق و هشام
G5: حساب م جمعة علام | O5: حساب م هشام | W5: حساب ح طارق | AF5: م جمعة علام
F8: ملاحظات | G8: المبلغ | H8: البيان | I8: مصدر الرصيد | J8: الرصيد | N8: ملاحظات | O8: المبغ | P8: البيان | R8: دفعة قديمة | S8: 240000 | V8: ملاحظات | W8: المبغ | X8: البيان | Z8: دفعة قديمة | AA8: 480000 | AF8: ملاحظات | AG8: المبلغ | AH8: البيان
F9: تصفية ح طارق | G9: 721613 | H9: الماضي | I9: الحساب القديم | J9: 520000 | O9: 100000 | P9: شروق | R9: اجمالي المصروفات | S9: =SUM(O9:O24) -> 383500 | W9: 45820 | X9: انتر لوك | Z9: اجمالي المصروفات | AA9: =SUM(W9:W10) -> 135820 | AF9: اول مرة | AG9: 65000 | AH9: حديد الترابزيت السور
I10: احمد كامل | J10: 40000 | O10: 58000 | P10: كراسي بلاستيك | R10: الاجمالي | S10: =SUM(S8:S9) -> 623500 | W10: 90000 | X10: شاشات | Z10: الاجمالي | AA10: =SUM(AA8:AA9) -> 615820 | AG10: 54000 | AH10: باقي قيمة العقد
I11: احمد كامل | J11: 68000 | O11: 30000 | P11: تيك اواي | AG11: 5000 | AH11: باقي من مصفة الكهرباء من الداخل
G12: 14500 | H12: ديب فريزر | O12: 40000 | P12: كاميرات | AF12: اول مره | AG12: 6000 | AH12: دهانات للسور
G13: 20000 | H13: دفعة ساوند | O13: 10000 | P13: مصاريف و عشاء | AF13: طارق | AG13: 2800 | AH13: فرق خشب بلدي
G14: 10000 | H14: شروق | O14: 16000 | P14: دومنا و شطرنج | AG14: 400 | AH14: خشب بلدي نقل
G15: 10500 | H15: جهاز انترنت | O15: 35000 | P15: باقي حساب الطقم الخارجي | AF15: من ابراهيم | AG15: 2500 | AH15: اصلاح المياه من الشركة الوطنية
G16: 8000 | H16: جهازين تابلت | O16: 20000 | P16: حساب الفرش الداخلي | AG16: 11000 | AH16: ماكينة قص النجيل
G17: 10400 | H17: عداد مياه و كهرباء | O17: 8500 | P17: تركيب الشاشات و الدش | AF17: اول مره | AG17: 450 | AH17: بنزين للماكينة
G18: 46500 | H18: كراسي | O18: 2500 | P18: اعلام | AF18: تاني مره | AG18: 53000 | AH18: حديد البروجلات + التاندة
G19: 30000 | H19: ديب فريزر الاسكا | O19: 8500 | P19: الكونتر | AF19: عايز 20 | AG19: 20000 | AH19: مصفة بروجولات وتاندة
F20: 1 | G20: 17800 | H20: تلاجة | O20: 3500 | P20: حداد | AG20: 72500 | AH20: ثلاجتان عرض +ايس ميكر
F21: 2 | G21: 17800 | H21: تلاجة | O21: 11500 | P21: مشتريات ومون | AG21: 1500 | AH21: مرتجع ثلاجة (كسر)
G22: 2500 | H22: مروحة فريش | O22: 40000 | P22: محطه مياه | AG22: 147000 | AH22: ادوات البار حسام الجندي
AG23: 156000 | AH23: ماكينه شابلاي + مطحة حسام الجندي
AG24: 29000 | AH24: فرش من الداخل هشام
I25: =SUM(J9:J11) -> 628000 | J25: اجمالي الرصيد | AG25: 3850 | AH25: مريات الحمامات
I26: =SUM(G9:G22) -> 909613 | J26: اجمالي المصروفات | AG26: 1000 | AH26: مشوار عربية يوم وسط البلد قرية هاني
I27: =909613-628000 -> 281613 | J27: المطلوب | W27: اجمالي المصاريف | AG27: 3800 | AH27: تقفيلة تحت الحوض
W28: م جمعة | X28: 848363 | AG28: 2500 | AH28: ونش رفع البرجيلة
W29: م هشام | X29: 623500 | AG29: 2500 | AH29: تعديل رخامة المطبخ
